2024-11-13 10:24:55,127 - AppLogger - ERROR - Error loading JSON: 'SettingsDialog' object has no attribute 'filter_list'
2024-11-13 10:24:59,010 - AppLogger - ERROR - Error loading JSON: 'SettingsDialog' object has no attribute 'filter_list'
2024-11-13 10:49:32,937 - AppLogger - ERROR - Error loading JSON: 'SettingsDialog' object has no attribute 'get_exclusions'
2024-11-13 11:08:23,240 - AppLogger - ERROR - Error loading JSON: 'SettingsDialog' object has no attribute 'get_exclusions'
2024-11-13 11:15:55,685 - AppLogger - ERROR - Error loading JSON: 'list' object has no attribute 'items'
2024-11-13 11:17:45,793 - AppLogger - ERROR - Error loading JSON: 'list' object has no attribute 'items'
2024-11-13 11:20:33,902 - AppLogger - ERROR - Error loading JSON: 'list' object has no attribute 'items'
2024-11-13 11:22:02,435 - AppLogger - ERROR - Error loading JSON: 'list' object has no attribute 'items'
2024-11-13 11:27:13,570 - AppLogger - ERROR - sr_type_exclusions is not a dictionary.
2024-11-13 11:27:13,571 - AppLogger - ERROR - group_exclusions is not a dictionary.
2024-11-13 11:27:13,571 - AppLogger - ERROR - no_location_sr_exclusions is not a dictionary.
2024-11-13 11:27:13,571 - AppLogger - ERROR - no_location_group_exclusions is not a dictionary.
2024-11-13 11:27:13,571 - AppLogger - ERROR - no_location_included_sr_exclusions is not a dictionary.
2024-11-13 11:27:13,571 - AppLogger - ERROR - no_location_included_group_exclusions is not a dictionary.
2024-11-13 11:29:29,904 - AppLogger - ERROR - sr_type_exclusions is not a dictionary.
2024-11-13 11:29:29,904 - AppLogger - ERROR - group_exclusions is not a dictionary.
2024-11-13 11:29:29,904 - AppLogger - ERROR - no_location_sr_exclusions is not a dictionary.
2024-11-13 11:29:29,904 - AppLogger - ERROR - no_location_group_exclusions is not a dictionary.
2024-11-13 11:29:29,904 - AppLogger - ERROR - no_location_included_sr_exclusions is not a dictionary.
2024-11-13 11:29:29,904 - AppLogger - ERROR - no_location_included_group_exclusions is not a dictionary.
2024-11-13 11:53:40,995 - AppLogger - ERROR - Error loading JSON: 'SettingsDialog' object has no attribute 'populate_list_with_checkboxes'
2024-11-13 13:24:29,698 - AppLogger - ERROR - Traceback (most recent call last):
  File "/Users/ryanwybenga/Desktop/Development/COOP/Excel-Report_Generator/modules/dialogs/settings_dialog.py", line 265, in save_settings
    'enable_no_location_included': self.no_location_include_card.isChecked(),  # Replace with actual enable checkbox reference
                                   ^^^^^^^^^^^^^^^^^^^^^^^^^^^^^
AttributeError: 'SettingsDialog' object has no attribute 'no_location_include_card'
2024-11-13 13:31:34,317 - AppLogger - ERROR - Traceback (most recent call last):
  File "/Users/ryanwybenga/Desktop/Development/COOP/Excel-Report_Generator/modules/dialogs/settings_dialog.py", line 262, in save_settings
    'enable_excluded': self.exclude_enable_checkbox.isChecked(),
                       ^^^^^^^^^^^^^^^^^^^^^^^^^^^^^^^^^^^^^^
AttributeError: 'NoneType' object has no attribute 'isChecked'
2024-11-13 15:10:35,221 - AppLogger - ERROR - Failed to save report: name 'grand_totals' is not defined
2024-11-13 21:21:29,974 - AppLogger - ERROR - Traceback (most recent call last):
  File "/Users/ryanwybenga/Desktop/Development/COOP/Excel-Report_Generator/modules/main_menu/settings_handler.py", line 59, in save_settings
    self.main_app.reload_stylesheet()  # Apply the new theme immediately
    ^^^^^^^^^^^^^^^^^^^^^^^^^^^^^^^
AttributeError: 'MainWindow' object has no attribute 'reload_stylesheet'. Did you mean: 'apply_stylesheet'?
2024-11-13 21:22:15,164 - AppLogger - ERROR - Traceback (most recent call last):
  File "/Users/ryanwybenga/Desktop/Development/COOP/Excel-Report_Generator/modules/main_menu/settings_handler.py", line 59, in save_settings
    self.main_app.reload_stylesheet()  # Apply the new theme immediately
    ^^^^^^^^^^^^^^^^^^^^^^^^^^^^^^^
AttributeError: 'MainWindow' object has no attribute 'reload_stylesheet'. Did you mean: 'apply_stylesheet'?
2024-11-14 09:37:39,157 - AppLogger - ERROR - Traceback (most recent call last):
  File "/Users/ryanwybenga/Desktop/Development/COOP/Excel-Report_Generator/modules/sr_counter/sr_counter_ui.py", line 257, in load_excel
    def load_excel(self):

KeyboardInterrupt
2024-11-14 10:37:17,113 - AppLogger - ERROR - Error during report generation: 'Month'
2024-11-14 11:47:01,625 - AppLogger - ERROR - Error generating preview: 'ReportGenerator' object has no attribute 'show_report_preview'
2024-11-14 12:37:34,418 - AppLogger - ERROR - Failed to save report: name 'total_format' is not defined
2024-11-14 12:50:06,092 - AppLogger - ERROR - Error during report generation: 'ReportGenerator' object has no attribute 'is_totals_row_present'
2024-11-14 14:03:58,585 - AppLogger - ERROR - Error during report generation: 'Jan'
2024-11-14 14:13:52,128 - AppLogger - ERROR - Error during report generation: 'Jan'
2024-11-14 14:48:02,005 - AppLogger - ERROR - Error during report generation: ReportGenerator.generate_report() got an unexpected keyword argument 'sort_by'
2024-11-14 14:53:31,551 - AppLogger - ERROR - Preview report has not been generated.
2024-11-14 14:53:38,769 - AppLogger - ERROR - Error generating preview: ReportGenerator.generate_report() got an unexpected keyword argument 'sort_by'
2024-11-14 14:54:40,220 - AppLogger - ERROR - Error generating preview: ReportGenerator.generate_report() got an unexpected keyword argument 'sort_by'
2024-11-14 15:03:07,552 - AppLogger - ERROR - Error during report generation: ReportGenerator.generate_report() got an unexpected keyword argument 'sort_by'
2024-11-14 15:05:37,416 - AppLogger - ERROR - Error during report generation: 'ReportGenerator' object has no attribute 'report_generator'
2024-11-14 15:05:37,419 - AppLogger - ERROR - Error during report generation: critical(parent: Optional[QWidget], title: Optional[str], text: Optional[str], buttons: QMessageBox.StandardButton = QMessageBox.Ok, defaultButton: QMessageBox.StandardButton = QMessageBox.NoButton): argument 1 has unexpected type 'ReportGenerator'
2024-11-14 15:06:02,700 - AppLogger - ERROR - Error during report generation: 'ReportGenerator' object has no attribute 'report_generator'
2024-11-14 15:06:02,701 - AppLogger - ERROR - Error during report generation: critical(parent: Optional[QWidget], title: Optional[str], text: Optional[str], buttons: QMessageBox.StandardButton = QMessageBox.Ok, defaultButton: QMessageBox.StandardButton = QMessageBox.NoButton): argument 1 has unexpected type 'ReportGenerator'
2024-11-14 15:08:31,817 - AppLogger - ERROR - Error during report generation: 'ReportGenerator' object has no attribute 'report_generator'
2024-11-14 15:08:31,819 - AppLogger - ERROR - Error during report generation: critical(parent: Optional[QWidget], title: Optional[str], text: Optional[str], buttons: QMessageBox.StandardButton = QMessageBox.Ok, defaultButton: QMessageBox.StandardButton = QMessageBox.NoButton): argument 1 has unexpected type 'ReportGenerator'
2024-11-14 15:13:32,026 - AppLogger - ERROR - Traceback (most recent call last):
  File "/Users/ryanwybenga/Desktop/Development/COOP/Excel-Report_Generator/modules/windows/main.py", line 93, in switch_to_sr_counter
    self.sr_counter = SRCounterUI(self)
                      ^^^^^^^^^^^^^^^^^
  File "/Users/ryanwybenga/Desktop/Development/COOP/Excel-Report_Generator/modules/sr_counter/sr_counter_ui.py", line 29, in __init__
    self.report_generator = ReportGenerator(self.progress_bar)
                            ^^^^^^^^^^^^^^^^^^^^^^^^^^^^^^^^^^
TypeError: ReportGenerator.__init__() missing 1 required positional argument: 'progress_bar'
2024-11-14 15:16:12,782 - AppLogger - ERROR - Error during report generation: 'ReportGenerator' object has no attribute 'report_generator'
2024-11-14 15:16:12,784 - AppLogger - ERROR - Error during report generation: critical(parent: Optional[QWidget], title: Optional[str], text: Optional[str], buttons: QMessageBox.StandardButton = QMessageBox.Ok, defaultButton: QMessageBox.StandardButton = QMessageBox.NoButton): argument 1 has unexpected type 'ReportGenerator'
2024-11-15 08:10:07,925 - AppLogger - ERROR - Error generating report: 'Month'
2024-11-15 11:12:40,659 - AppLogger - ERROR - Error generating report: 'ReportGenerator' object has no attribute '_append_totals'
2024-11-15 13:06:53,209 - AppLogger - ERROR - Traceback (most recent call last):
  File "/Users/ryanwybenga/Desktop/Development/COOP/Excel-Report_Generator/modules/main_menu/main_menu_ui.py", line 72, in open_settings_dialog
    dialog = SettingsHandler(main_app=self.main_window)
             ^^^^^^^^^^^^^^^^^^^^^^^^^^^^^^^^^^^^^^^^^^
  File "/Users/ryanwybenga/Desktop/Development/COOP/Excel-Report_Generator/modules/main_menu/settings_handler.py", line 110, in __init__
    self.settings = AppSettings()
                    ^^^^^^^^^^^
NameError: name 'AppSettings' is not defined
2024-11-15 13:14:28,568 - AppLogger - ERROR - Traceback (most recent call last):
  File "/Users/ryanwybenga/Desktop/Development/COOP/Excel-Report_Generator/modules/main_menu/settings_handler.py", line 70, in open_groups_dialog
    dialog = EditableTableDialog(self.groups_data, ["Group"], self)
             ^^^^^^^^^^^^^^^^^^^^^^^^^^^^^^^^^^^^^^^^^^^^^^^^^^^^^^
TypeError: EditableTableDialog.__init__() takes from 2 to 3 positional arguments but 4 were given
2024-11-15 13:20:55,522 - AppLogger - ERROR - Traceback (most recent call last):
  File "/Users/ryanwybenga/Desktop/Development/COOP/Excel-Report_Generator/modules/main_menu/settings_handler.py", line 57, in open_types_dialog
    dialog = EditableTableDialog(["Type"], "311_GIS_Type_Descriptions.xlsx", self)
             ^^^^^^^^^^^^^^^^^^^^^^^^^^^^^^^^^^^^^^^^^^^^^^^^^^^^^^^^^^^^^^^^^^^^^
  File "/Users/ryanwybenga/Desktop/Development/COOP/Excel-Report_Generator/modules/dialogs/editable_table_dialog.py", line 19, in __init__
    self.data = self.load_data_from_excel()  # Load data on initialization
                ^^^^^^^^^^^^^^^^^^^^^^^^^^^
  File "/Users/ryanwybenga/Desktop/Development/COOP/Excel-Report_Generator/modules/dialogs/editable_table_dialog.py", line 69, in load_data_from_excel
    return [tuple(row) for row in data.values] if data is not None else []
           ^^^^^^^^^^^^^^^^^^^^^^^^^^^^^^^^^^^
TypeError: 'builtin_function_or_method' object is not iterable
2024-11-21 09:52:43,805 - AppLogger - ERROR - Error checking for updates: ('Connection aborted.', ConnectionResetError(54, 'Connection reset by peer'))
2024-11-21 10:30:06,595 - AppLogger - ERROR - Error checking for updates: ('Connection aborted.', ConnectionResetError(54, 'Connection reset by peer'))
2024-11-27 13:53:06,824 - AppLogger - ERROR - Error checking for updates: ('Connection aborted.', ConnectionResetError(54, 'Connection reset by peer'))
2024-12-02 08:13:52,932 - AppLogger - ERROR - Error checking for updates: ('Connection aborted.', ConnectionResetError(54, 'Connection reset by peer'))
2024-12-02 09:27:50,141 - AppLogger - ERROR - Error checking for updates: ('Connection aborted.', ConnectionResetError(54, 'Connection reset by peer'))
2024-12-02 09:45:50,078 - AppLogger - ERROR - Error checking for updates: ('Connection aborted.', ConnectionResetError(54, 'Connection reset by peer'))
2024-12-02 09:49:47,288 - AppLogger - ERROR - Error checking for updates: ('Connection aborted.', ConnectionResetError(54, 'Connection reset by peer'))
2024-12-02 15:04:07,757 - AppLogger - ERROR - Error checking for updates: HTTPSConnectionPool(host='raw.githubusercontent.com', port=443): Read timed out. (read timeout=10)
2024-12-03 08:08:32,828 - AppLogger - ERROR - Error checking for updates: ('Connection aborted.', ConnectionResetError(54, 'Connection reset by peer'))
2024-12-03 08:08:41,432 - AppLogger - ERROR - Error checking for updates: ('Connection aborted.', ConnectionResetError(54, 'Connection reset by peer'))
2024-12-04 14:17:03,406 - AppLogger - ERROR - Error checking for updates: ('Connection aborted.', ConnectionResetError(54, 'Connection reset by peer'))
2024-12-04 14:17:10,247 - AppLogger - ERROR - Error checking for updates: ('Connection aborted.', ConnectionResetError(54, 'Connection reset by peer'))
2024-12-04 14:20:32,854 - AppLogger - ERROR - Error checking for updates: ('Connection aborted.', ConnectionResetError(54, 'Connection reset by peer'))
2024-12-04 14:20:39,410 - AppLogger - ERROR - Traceback (most recent call last):
  File "/Users/ryanwybenga/Desktop/Development/COOP/Excel-Report_Generator/modules/main_menu/settings_handler.py", line 58, in open_types_dialog
    dialog = EditableTableDialog(["Type"], "311_GIS_Type_Descriptions.xlsx", self)
             ^^^^^^^^^^^^^^^^^^^^^^^^^^^^^^^^^^^^^^^^^^^^^^^^^^^^^^^^^^^^^^^^^^^^^
  File "/Users/ryanwybenga/Desktop/Development/COOP/Excel-Report_Generator/modules/dialogs/editable_table_dialog.py", line 21, in __init__
    self.file_path = self.ensure_writable_copy()
                     ^^^^^^^^^^^^^^^^^^^^^^^^^^^
  File "/Users/ryanwybenga/Desktop/Development/COOP/Excel-Report_Generator/modules/dialogs/editable_table_dialog.py", line 32, in ensure_writable_copy
    writable_path = FileHelper.get_writable_resource_path(os.path.join('Excel', self.excel_file_key))
                    ^^^^^^^^^^^^^^^^^^^^^^^^^^^^^^^^^^^^^
AttributeError: type object 'FileHelper' has no attribute 'get_writable_resource_path'
2024-12-04 14:21:34,117 - AppLogger - ERROR - Error checking for updates: ('Connection aborted.', ConnectionResetError(54, 'Connection reset by peer'))
2024-12-04 14:47:28,796 - AppLogger - ERROR - Error checking for updates: ('Connection aborted.', ConnectionResetError(54, 'Connection reset by peer'))
2024-12-04 14:47:37,787 - AppLogger - ERROR - Traceback (most recent call last):
  File "/Users/ryanwybenga/Desktop/Development/COOP/Excel-Report_Generator/modules/dialogs/editable_table_dialog.py", line 121, in save_changes_to_excel
    FileHelper.save_excel(df, file_path)
    ^^^^^^^^^^^^^^^^^^^^^
AttributeError: type object 'FileHelper' has no attribute 'save_excel'
2024-12-04 14:48:16,656 - AppLogger - ERROR - Error checking for updates: ('Connection aborted.', ConnectionResetError(54, 'Connection reset by peer'))
2024-12-04 14:49:57,277 - AppLogger - ERROR - Error checking for updates: ('Connection aborted.', ConnectionResetError(54, 'Connection reset by peer'))
2024-12-04 14:57:37,377 - AppLogger - ERROR - Error checking for updates: ('Connection aborted.', ConnectionResetError(54, 'Connection reset by peer'))
2024-12-04 14:58:20,864 - AppLogger - ERROR - Error checking for updates: ('Connection aborted.', ConnectionResetError(54, 'Connection reset by peer'))
2024-12-04 15:10:37,471 - AppLogger - ERROR - Error checking for updates: ('Connection aborted.', ConnectionResetError(54, 'Connection reset by peer'))
2024-12-04 15:10:40,343 - AppLogger - ERROR - Traceback (most recent call last):
  File "/Users/ryanwybenga/Desktop/Development/COOP/Excel-Report_Generator/modules/main_menu/settings_handler.py", line 58, in open_types_dialog
    dialog = EditableTableDialog(["Type"], "311_GIS_Type_Descriptions.xlsx", self)
             ^^^^^^^^^^^^^^^^^^^^^^^^^^^^^^^^^^^^^^^^^^^^^^^^^^^^^^^^^^^^^^^^^^^^^
  File "/Users/ryanwybenga/Desktop/Development/COOP/Excel-Report_Generator/modules/dialogs/editable_table_dialog.py", line 19, in __init__
    self.data = self.load_data_from_excel()  # Load data on initialization
                ^^^^^^^^^^^^^^^^^^^^^^^^^^^
  File "/Users/ryanwybenga/Desktop/Development/COOP/Excel-Report_Generator/modules/dialogs/editable_table_dialog.py", line 70, in load_data_from_excel
    file_path = FileHelper.ensure_writable_copy(f"resources/Excel/{self.excel_file_key}")
                ^^^^^^^^^^^^^^^^^^^^^^^^^^^^^^^
AttributeError: type object 'FileHelper' has no attribute 'ensure_writable_copy'
2024-12-04 15:14:50,643 - AppLogger - ERROR - Error checking for updates: ('Connection aborted.', ConnectionResetError(54, 'Connection reset by peer'))
2024-12-04 15:22:57,319 - AppLogger - ERROR - Error checking for updates: ('Connection aborted.', ConnectionResetError(54, 'Connection reset by peer'))
2024-12-04 15:26:50,694 - AppLogger - ERROR - Error checking for updates: ('Connection aborted.', ConnectionResetError(54, 'Connection reset by peer'))
2024-12-04 15:28:40,228 - AppLogger - ERROR - Error checking for updates: ('Connection aborted.', ConnectionResetError(54, 'Connection reset by peer'))
2024-12-04 15:31:02,397 - AppLogger - ERROR - Error checking for updates: ('Connection aborted.', ConnectionResetError(54, 'Connection reset by peer'))
2024-12-05 08:02:30,658 - AppLogger - ERROR - Error checking for updates: ('Connection aborted.', ConnectionResetError(54, 'Connection reset by peer'))
2024-12-05 11:23:34,248 - AppLogger - ERROR - Error checking for updates: ('Connection aborted.', ConnectionResetError(54, 'Connection reset by peer'))
2024-12-05 11:34:01,166 - AppLogger - ERROR - Error checking for updates: ('Connection aborted.', ConnectionResetError(54, 'Connection reset by peer'))
2024-12-05 11:39:31,094 - AppLogger - ERROR - Error checking for updates: ('Connection aborted.', ConnectionResetError(54, 'Connection reset by peer'))
2024-12-05 11:45:52,817 - AppLogger - ERROR - Error checking for updates: ('Connection aborted.', ConnectionResetError(54, 'Connection reset by peer'))
2024-12-05 11:48:16,195 - AppLogger - ERROR - Error checking for updates: ('Connection aborted.', ConnectionResetError(54, 'Connection reset by peer'))
2024-12-05 11:54:06,269 - AppLogger - ERROR - Error checking for updates: ('Connection aborted.', ConnectionResetError(54, 'Connection reset by peer'))
2024-12-05 13:31:50,155 - AppLogger - ERROR - Error checking for updates: ('Connection aborted.', ConnectionResetError(54, 'Connection reset by peer'))
2024-12-05 15:26:03,414 - AppLogger - ERROR - Error checking for updates: ('Connection aborted.', ConnectionResetError(54, 'Connection reset by peer'))
2024-12-05 15:26:08,264 - AppLogger - ERROR - Traceback (most recent call last):
  File "/Users/ryanwybenga/Desktop/Development/COOP/Excel-Report_Generator/modules/windows/main.py", line 77, in switch_to_sr_counter
    self.sr_counter = SRCounterUI(self)
                      ^^^^^^^^^^^^^^^^^
  File "/Users/ryanwybenga/Desktop/Development/COOP/Excel-Report_Generator/modules/sr_counter/sr_counter_ui.py", line 27, in __init__
    self.setup_ui()
  File "/Users/ryanwybenga/Desktop/Development/COOP/Excel-Report_Generator/modules/sr_counter/sr_counter_ui.py", line 44, in setup_ui
    sidebar = self.setup_sidebar()  # Ensure sidebar is created only once
              ^^^^^^^^^^^^^^^^^^^^
  File "/Users/ryanwybenga/Desktop/Development/COOP/Excel-Report_Generator/modules/sr_counter/sr_counter_ui.py", line 64, in setup_sidebar
    clear_excel_button.clicked.connect(self.clear_excel)
                                       ^^^^^^^^^^^^^^^^
AttributeError: 'SRCounterUI' object has no attribute 'clear_excel'. Did you mean: 'load_excel'?
2024-12-06 08:34:55,784 - AppLogger - ERROR - Error checking for updates: ('Connection aborted.', ConnectionResetError(54, 'Connection reset by peer'))
2024-12-06 08:35:00,203 - AppLogger - ERROR - Traceback (most recent call last):
  File "/Users/ryanwybenga/Desktop/Development/COOP/Excel-Report_Generator/modules/windows/main.py", line 77, in switch_to_sr_counter
    self.sr_counter = SRCounterUI(self)
                      ^^^^^^^^^^^^^^^^^
  File "/Users/ryanwybenga/Desktop/Development/COOP/Excel-Report_Generator/modules/sr_counter/sr_counter_ui.py", line 27, in __init__
    self.setup_ui()
  File "/Users/ryanwybenga/Desktop/Development/COOP/Excel-Report_Generator/modules/sr_counter/sr_counter_ui.py", line 44, in setup_ui
    sidebar = self.setup_sidebar()  # Ensure sidebar is created only once
              ^^^^^^^^^^^^^^^^^^^^
  File "/Users/ryanwybenga/Desktop/Development/COOP/Excel-Report_Generator/modules/sr_counter/sr_counter_ui.py", line 64, in setup_sidebar
    clear_excel_button.clicked.connect(self.clear_excel)
                                       ^^^^^^^^^^^^^^^^
AttributeError: 'SRCounterUI' object has no attribute 'clear_excel'. Did you mean: 'load_excel'?
2024-12-06 08:48:14,921 - AppLogger - ERROR - Error checking for updates: ('Connection aborted.', ConnectionResetError(54, 'Connection reset by peer'))
2024-12-06 08:48:32,902 - AppLogger - ERROR - Traceback (most recent call last):
  File "/Users/ryanwybenga/Desktop/Development/COOP/Excel-Report_Generator/modules/windows/main.py", line 77, in switch_to_sr_counter
    self.sr_counter = SRCounterUI(self)
                      ^^^^^^^^^^^^^^^^^
  File "/Users/ryanwybenga/Desktop/Development/COOP/Excel-Report_Generator/modules/sr_counter/sr_counter_ui.py", line 27, in __init__
    self.setup_ui()
  File "/Users/ryanwybenga/Desktop/Development/COOP/Excel-Report_Generator/modules/sr_counter/sr_counter_ui.py", line 44, in setup_ui
    sidebar = self.setup_sidebar()  # Ensure sidebar is created only once
              ^^^^^^^^^^^^^^^^^^^^
  File "/Users/ryanwybenga/Desktop/Development/COOP/Excel-Report_Generator/modules/sr_counter/sr_counter_ui.py", line 64, in setup_sidebar
    clear_excel_button.clicked.connect(self.clear_excel)
                                       ^^^^^^^^^^^^^^^^
AttributeError: 'SRCounterUI' object has no attribute 'clear_excel'. Did you mean: 'load_excel'?
2024-12-06 08:49:09,076 - AppLogger - ERROR - Error checking for updates: ('Connection aborted.', ConnectionResetError(54, 'Connection reset by peer'))
2024-12-06 08:49:22,984 - AppLogger - ERROR - Traceback (most recent call last):
  File "/Users/ryanwybenga/Desktop/Development/COOP/Excel-Report_Generator/modules/windows/main.py", line 77, in switch_to_sr_counter
    self.sr_counter = SRCounterUI(self)
                      ^^^^^^^^^^^^^^^^^
  File "/Users/ryanwybenga/Desktop/Development/COOP/Excel-Report_Generator/modules/sr_counter/sr_counter_ui.py", line 27, in __init__
    self.setup_ui()
  File "/Users/ryanwybenga/Desktop/Development/COOP/Excel-Report_Generator/modules/sr_counter/sr_counter_ui.py", line 44, in setup_ui
    sidebar = self.setup_sidebar()  # Ensure sidebar is created only once
              ^^^^^^^^^^^^^^^^^^^^
  File "/Users/ryanwybenga/Desktop/Development/COOP/Excel-Report_Generator/modules/sr_counter/sr_counter_ui.py", line 68, in setup_sidebar
    settings_button.clicked.connect(self.open_settings_dialog)
                                    ^^^^^^^^^^^^^^^^^^^^^^^^^
AttributeError: 'SRCounterUI' object has no attribute 'open_settings_dialog'
2024-12-06 09:21:17,908 - AppLogger - ERROR - Error checking for updates: ('Connection aborted.', ConnectionResetError(54, 'Connection reset by peer'))
2024-12-06 09:21:19,149 - AppLogger - ERROR - Traceback (most recent call last):
  File "/Users/ryanwybenga/Desktop/Development/COOP/Excel-Report_Generator/modules/windows/main.py", line 77, in switch_to_sr_counter
    self.sr_counter = SRCounterUI(self)
                      ^^^^^^^^^^^^^^^^^
  File "/Users/ryanwybenga/Desktop/Development/COOP/Excel-Report_Generator/modules/sr_counter/sr_counter_ui.py", line 26, in __init__
    self.setup_ui()
  File "/Users/ryanwybenga/Desktop/Development/COOP/Excel-Report_Generator/modules/sr_counter/sr_counter_ui.py", line 44, in setup_ui
    sr_counter_panel = self.setup_main_panel()
                       ^^^^^^^^^^^^^^^^^^^^^^^
  File "/Users/ryanwybenga/Desktop/Development/COOP/Excel-Report_Generator/modules/sr_counter/sr_counter_ui.py", line 101, in setup_main_panel
    self.sort_by_dropdown.currentIndexChanged.connect(self.on_sort_by_changed)
                                                      ^^^^^^^^^^^^^^^^^^^^^^^
AttributeError: 'SRCounterUI' object has no attribute 'on_sort_by_changed'
2024-12-06 09:33:34,646 - AppLogger - ERROR - Error checking for updates: ('Connection aborted.', ConnectionResetError(54, 'Connection reset by peer'))
2024-12-06 09:33:35,830 - AppLogger - ERROR - Traceback (most recent call last):
  File "/Users/ryanwybenga/Desktop/Development/COOP/Excel-Report_Generator/modules/windows/main.py", line 77, in switch_to_sr_counter
    self.sr_counter = SRCounterUI(self)
                      ^^^^^^^^^^^^^^^^^
  File "/Users/ryanwybenga/Desktop/Development/COOP/Excel-Report_Generator/modules/sr_counter/sr_counter_ui.py", line 31, in __init__
    self.checkbox_manager = CheckboxManager(self.columns_layout)
                                            ^^^^^^^^^^^^^^^^^^^
AttributeError: 'SRCounterUI' object has no attribute 'columns_layout'
2024-12-06 09:41:43,183 - AppLogger - ERROR - Error checking for updates: ('Connection aborted.', ConnectionResetError(54, 'Connection reset by peer'))
2024-12-06 09:58:22,966 - AppLogger - ERROR - Error checking for updates: ('Connection aborted.', ConnectionResetError(54, 'Connection reset by peer'))
2024-12-06 09:58:24,688 - AppLogger - ERROR - Traceback (most recent call last):
  File "/Users/ryanwybenga/Desktop/Development/COOP/Excel-Report_Generator/modules/windows/main.py", line 77, in switch_to_sr_counter
    self.sr_counter = SRCounterUI(self)
                      ^^^^^^^^^^^^^^^^^
  File "/Users/ryanwybenga/Desktop/Development/COOP/Excel-Report_Generator/modules/sr_counter/sr_counter_ui.py", line 26, in __init__
    self.setup_ui()
  File "/Users/ryanwybenga/Desktop/Development/COOP/Excel-Report_Generator/modules/sr_counter/sr_counter_ui.py", line 50, in setup_ui
    sr_counter_panel = self.setup_main_panel()
                       ^^^^^^^^^^^^^^^^^^^^^^^
  File "/Users/ryanwybenga/Desktop/Development/COOP/Excel-Report_Generator/modules/sr_counter/sr_counter_ui.py", line 129, in setup_main_panel
    self.start_time_input = QTimeEdit()
                            ^^^^^^^^^
NameError: name 'QTimeEdit' is not defined. Did you mean: 'QDateTimeEdit'?
2024-12-06 10:00:07,041 - AppLogger - ERROR - Error checking for updates: ('Connection aborted.', ConnectionResetError(54, 'Connection reset by peer'))
2024-12-06 10:11:55,419 - AppLogger - ERROR - Error checking for updates: ('Connection aborted.', ConnectionResetError(54, 'Connection reset by peer'))
2024-12-06 10:11:57,168 - AppLogger - ERROR - Traceback (most recent call last):
  File "/Users/ryanwybenga/Desktop/Development/COOP/Excel-Report_Generator/modules/windows/main.py", line 77, in switch_to_sr_counter
    self.sr_counter = SRCounterUI(self)
                      ^^^^^^^^^^^^^^^^^
  File "/Users/ryanwybenga/Desktop/Development/COOP/Excel-Report_Generator/modules/sr_counter/sr_counter_ui.py", line 26, in __init__
    self.setup_ui()
  File "/Users/ryanwybenga/Desktop/Development/COOP/Excel-Report_Generator/modules/sr_counter/sr_counter_ui.py", line 50, in setup_ui
    sr_counter_panel = self.setup_main_panel()
                       ^^^^^^^^^^^^^^^^^^^^^^^
  File "/Users/ryanwybenga/Desktop/Development/COOP/Excel-Report_Generator/modules/sr_counter/sr_counter_ui.py", line 113, in setup_main_panel
    self.start_date_input = QDateEdit()
                            ^^^^^^^^^
NameError: name 'QDateEdit' is not defined. Did you mean: 'QTimeEdit'?
2024-12-06 10:12:54,248 - AppLogger - ERROR - Error checking for updates: ('Connection aborted.', ConnectionResetError(54, 'Connection reset by peer'))
2024-12-06 10:22:01,382 - AppLogger - ERROR - Error checking for updates: ('Connection aborted.', ConnectionResetError(54, 'Connection reset by peer'))
2024-12-06 10:33:52,156 - AppLogger - ERROR - Error checking for updates: ('Connection aborted.', ConnectionResetError(54, 'Connection reset by peer'))
2024-12-06 11:26:35,034 - AppLogger - ERROR - Error checking for updates: ('Connection aborted.', ConnectionResetError(54, 'Connection reset by peer'))
2024-12-06 11:44:12,901 - AppLogger - ERROR - Error checking for updates: ('Connection aborted.', ConnectionResetError(54, 'Connection reset by peer'))
2024-12-06 11:44:39,816 - AppLogger - ERROR - Error saving report: ReportGenerator._save_to_excel() takes from 3 to 5 positional arguments but 7 were given
2024-12-06 11:44:51,714 - AppLogger - ERROR - Error saving report: ReportGenerator._save_to_excel() takes from 3 to 5 positional arguments but 7 were given
2024-12-06 11:46:58,629 - AppLogger - ERROR - Error checking for updates: ('Connection aborted.', ConnectionResetError(54, 'Connection reset by peer'))
2024-12-06 11:47:52,423 - AppLogger - ERROR - Error saving report: ReportGenerator._save_to_excel() takes from 3 to 5 positional arguments but 7 were given
2024-12-06 11:50:14,747 - AppLogger - ERROR - Error checking for updates: ('Connection aborted.', ConnectionResetError(54, 'Connection reset by peer'))
2024-12-06 11:50:42,678 - AppLogger - ERROR - Failed to save Excel file: 'MergedCell' object has no attribute 'column_letter'
2024-12-06 11:51:17,247 - AppLogger - ERROR - Failed to save Excel file: 'MergedCell' object has no attribute 'column_letter'
2024-12-06 11:53:23,330 - AppLogger - ERROR - Error checking for updates: ('Connection aborted.', ConnectionResetError(54, 'Connection reset by peer'))
2024-12-06 11:53:56,397 - AppLogger - ERROR - Failed to save Excel file: 'MergedCell' object has no attribute 'column_letter'
2024-12-06 12:35:13,713 - AppLogger - ERROR - Error checking for updates: ('Connection aborted.', ConnectionResetError(54, 'Connection reset by peer'))
2024-12-06 12:35:36,544 - AppLogger - ERROR - Failed to save Excel file: 'MergedCell' object has no attribute 'column_letter'
2024-12-06 12:51:11,461 - AppLogger - ERROR - Error checking for updates: ('Connection aborted.', ConnectionResetError(54, 'Connection reset by peer'))
2024-12-06 12:57:34,734 - AppLogger - ERROR - Error checking for updates: ('Connection aborted.', ConnectionResetError(54, 'Connection reset by peer'))
2024-12-06 13:05:34,319 - AppLogger - ERROR - Error checking for updates: ('Connection aborted.', ConnectionResetError(54, 'Connection reset by peer'))
